Workbook

Sheet Civil_Debt_Cases
A1: Case Identification | I1: Parties | N1: Filing & Initiation | P1: Service of Process | W1: Adjudication Phase | AA1: Execution Initiation | AE1: Mode of Execution | AJ1: Execution Outcome | AM1: Court Discretion & Norms | AQ1: Case Trajectory
A2: Case_ID | B2: Province | C2: District | D2: Court_Name | E2: Court_Level | F2: Year_Filed | G2: Case_Type | H2: Claim_Value_Band | I2: Creditor_Type | J2: Creditor_Individual_or_Firm | K2: Debtor_Status | L2: Vakil_For_Creditor | M2: Vakil_For_Debtor | N2: Filing_Mode | O2: Filing_Notes | P2: Service_Attempted | Q2: Service_Outcome | R2: Time_To_Service | S2: Defendant_Appeared | T2: Default | U2: Absconding_Noted | V2: Absconding_Description | W2: Number_of_Adjournments | X2: Adjournment_Cause_Main | Y2: Decree_Type | Z2: Time_To_Decree | AA2: Execution_Filed | AB2: Time_To_Execution | AC2: Execution_Stayed | AD2: Installments_Ordered | AE2: Execution_Mode_Primary | AF2: Land_Attached | AG2: Auction_Ordered | AH2: Auction_Conducted | AI2: Valuation_Dispute | AJ2: Execution_Outcome | AK2: Case_Closed | AL2: Closure_Mode | AM2: Customary_Norms_Referenced | AN2: Revenue_Official_Involved | AO2: Court_Defers_To_Custom | AP2: Judicial_Discretion_Notes | AQ2: Procedural_Trajectory | AR2: Analyst_Confidence | AS2: Coding_Notes
A3: Unique ID (e.g. BOM_Poona_1878_034) | B3: Bombay / Punjab / Bengal / Madras | C3: District name | D3: Name of court | E3: Munsif / Subordinate Judge / District Judge | F3: Year plaint filed | G3: Debt / Mortgage / Mixed | H3: Low / Medium / High (define once in codebook) | I3: Moneylender / Merchant / Landlord / Firm | J3: Individual / Firm | K3: Cultivator / Tenant / Landholder | L3: Yes / No | M3: Yes / No | N3: Single plaint / Batch filing | O3: Short free text (max 1–2 lines) | P3: Yes / No | Q3: Successful / Delayed / Failed | R3: <1 month / 1–3 months / >3 months | S3: Yes / No | T3: Yes / No | U3: Yes / No | V3: Free text (verbatim wording if possible) | W3: Numeric | X3: Defendant absence / Creditor delay / Court | Y3: Contested / Ex parte | Z3: <6 months / 6–18 months / >18 months | AA3: Yes / No | AB3: <6 months / 6–18 months / >18 months | AC3: Yes / No | AD3: Yes / No | AE3: Cash / Moveables / Land | AF3: Yes / No | AG3: Yes / No | AH3: Yes / No | AI3: Yes / No | AJ3: Full recovery / Partial / Failed | AK3: Yes / No | AL3: Satisfaction / Withdrawal / Abandonment | AM3: Yes / No | AN3: Yes / No | AO3: Yes / No | AP3: Short free text | AQ3: Rapid enforcement / Delayed coercion / Procedural attrition / Negotiated exit / Jurisdictional evasion | AR3: High / Medium / Low | AS3: Free text (why you coded it this way)
A4: One row = one case = one procedural life-cycle. | I4: Judges | L4: Name /firm | M4: Name//firm | U4: “absconding to princely states” issue lives - as data, not theory. | AA4: Debt imprisonment
A5: BOM_KOL_1874_001 | B5: Bombay | C5: Kolaba | D5: Munsif Court, Kolaba | E5: Munsif | F5: 1874 | G5: Bond | H5: Low | I5: Merchant | J5: Individual | K5: Cultivator | L5: Yes | M5: Yes | N5: Single plaint | P5: Yes | Q5: Successful | R5: <1 month | S5: No | T5: Yes | U5: No | W5: 4 | X5: Defendant absence | Y5: Ex parte | Z5: <6 months | AA5: Yes | AB5: 6-18 months | AC5: No | AD5: No | AE5: Land | AF5: Yes | AG5: No | AH5: No | AI5: No | AJ5: Partial | AK5: Yes | AL5: Abandonment | AM5: No | AN5: No | AO5: No | AP5: No customary deference noted | AQ5: Delayed coercion | AR5: High | AS5: Full case bundle present.
A6: BOM_RAT_1903_002 | B6: Bombay | C6: Ratnagiri | D6: Munsif Court, Ratnagiri | E6: Munsif | F6: 1903 | G6: Debt | H6: Medium | I6: Moneylender | J6: Individual | K6: Landholder | L6: No | M6: No | N6: Single plaint | P6: Yes | Q6: Delayed | R6: >3 months | S6: No | T6: Yes | U6: Yes | V6: Reported absent in princely territory | W6: 3 | X6: Defendant absence | Y6: Ex parte | Z6: <6 months | AA6: Yes | AB6: >18 months | AC6: No | AD6: Yes | AE6: Cash | AF6: Yes | AG6: Yes | AH6: Yes | AI6: Yes | AJ6: Failed | AK6: No | AM6: No | AN6: Yes | AO6: No | AP6: No customary deference noted | AQ6: Procedural attrition | AR6: High | AS6: Full case bundle present.
A7: BOM_SHO_1905_003 | B7: Bombay | C7: Sholapur | D7: Munsif Court, Sholapur | E7: Munsif | F7: 1905 | G7: Bond | H7: High | I7: Moneylender | J7: Individual | K7: Tenant | L7: No | M7: No | N7: Batch filing | P7: Yes | Q7: Successful | R7: 1-3 months | S7: Yes | T7: No | U7: No | W7: 1 | X7: Court congestion | Y7: Contested | Z7: <6 months | AA7: Yes | AB7: 6-18 months | AC7: No | AD7: No | AE7: Land | AF7: Yes | AG7: Yes | AH7: Yes | AI7: Yes | AJ7: Full recovery | AK7: Yes | AL7: Abandonment | AM7: No | AN7: No | AO7: No | AP7: No customary deference noted | AQ7: Delayed coercion | AR7: High | AS7: Full case bundle present.
A8: BOM_NAS_1893_004 | B8: Bombay | C8: Nasik | D8: District Court, Nasik | E8: District Judge | F8: 1893 | G8: Mixed | H8: High | I8: Landlord | J8: Individual | K8: Tenant | L8: No | M8: No | N8: Single plaint | P8: Yes | Q8: Successful | R8: <1 month | S8: Yes | T8: No | U8: No | W8: 5 | X8: Defendant absence | Y8: Ex parte | Z8: 6-18 months | AA8: Yes | AB8: 6-18 months | AC8: No | AD8: No | AE8: Land | AF8: Yes | AG8: Yes | AH8: Yes | AI8: No | AJ8: Failed | AK8: No | AM8: No | AN8: No | AO8: No | AP8: No customary deference noted | AQ8: Delayed coercion | AR8: High | AS8: Full case bundle present.
A9: BOM_AHM_1918_005 | B9: Bombay | C9: Ahmednagar | D9: Munsif Court, Ahmednagar | E9: Munsif | F9: 1918 | G9: Bond | H9: High | I9: Merchant | J9: Individual | K9: Landholder | L9: No | M9: Yes | N9: Batch filing | P9: Yes | Q9: Successful | R9: <1 month | S9: Yes | T9: No | U9: No | W9: 0 | X9: Creditor delay | Y9: Ex parte | Z9: <6 months | AA9: No | AB9: >18 months | AC9: No | AD9: No | AE9: Cash | AF9: Yes | AG9: No | AH9: No | AI9: No | AJ9: Full recovery | AK9: Yes | AL9: Satisfaction | AM9: No | AN9: No | AO9: No | AP9: No customary deference noted | AQ9: Procedural attrition | AR9: High | AS9: Full case bundle present.
A10: BOM_KOL_1920_006 | B10: Bombay | C10: Kolaba | D10: District Court, Kolaba | E10: District Judge | F10: 1920 | G10: Mortgage | H10: Medium | I10: Firm | J10: Firm | K10: Tenant | L10: No | M10: No | N10: Batch filing | P10: Yes | Q10: Delayed | R10: 1-3 months | S10: No | T10: Yes | U10: No | W10: 3 | X10: Court congestion | Y10: Ex parte | Z10: 6-18 months | AA10: Yes | AB10: <6 months | AC10: Yes | AD10: No | AE10: Land | AF10: Yes | AG10: No | AH10: No | AI10: No | AJ10: Partial | AK10: Yes | AL10: Satisfaction | AM10: No | AN10: Yes | AO10: No | AP10: No customary deference noted | AQ10: Jurisdictional evasion | AR10: Medium | AS10: Case reconstructed from decree register; plaint missing.
A11: BOM_POO_1925_007 | B11: Bombay | C11: Poona | D11: Munsif Court, Poona | E11: Munsif | F11: 1925 | G11: Bond | H11: High | I11: Landlord | J11: Individual | K11: Proprietor | L11: Yes | M11: No | N11: Batch filing | P11: Yes | Q11: Delayed | R11: 1-3 months | S11: No | T11: Yes | U11: No | W11: 0 | X11: Defendant absence | Y11: Ex parte | Z11: 6-18 months | AA11: Yes | AB11: 6-18 months | AC11: No | AD11: No | AE11: Land | AF11: Yes | AG11: No | AH11: No | AI11: No | AJ11: Full recovery | AK11: Yes | AL11: Withdrawal | AM11: No | AN11: No | AO11: No | AP11: No customary deference noted | AQ11: Rapid enforcement | AR11: High | AS11: Full case bundle present.
A12: BOM_NAS_1917_008 | B12: Bombay | C12: Nasik | D12: Munsif Court, Nasik | E12: Munsif | F12: 1917 | G12: Mixed | H12: Low | I12: Trader | J12: Individual | K12: Cultivator | L12: No | M12: No | N12: Single plaint | P12: Yes | Q12: Delayed | R12: >3 months | S12: No | T12: Yes | U12: Yes | V12: Reported absent in princely territory | W12: 0 | X12: Court congestion | Y12: Ex parte | Z12: 6-18 months | AA12: Yes | AB12: <6 months | AC12: No | AD12: No | AE12: Moveables | AF12: No | AG12: No | AH12: No | AI12: No | AJ12: Full recovery | AK12: Yes | AL12: Withdrawal | AM12: No | AN12: No | AO12: No | AP12: No customary deference noted | AQ12: Rapid enforcement | AR12: High | AS12: Full case bundle present.
A13: BOM_SAT_1893_009 | B13: Bombay | C13: Satara | D13: Court of the Sub. Judge, Satara | E13: Subordinate Judge | F13: 1893 | G13: Bond | H13: Medium | I13: Firm | J13: Firm | K13: Tenant | L13: No | M13: No | N13: Batch filing | P13: Yes | Q13: Successful | R13: <1 month | S13: Yes | T13: No | U13: No | W13: 0 | X13: Court congestion | Y13: Contested | Z13: <6 months | AA13: Yes | AB13: >18 months | AC13: No | AD13: Yes | AE13: Land | AF13: Yes | AG13: Yes | AH13: No | AI13: No | AJ13: Failed | AK13: No | AM13: No | AN13: Yes | AO13: No | AP13: No customary deference noted | AQ13: Negotiated exit | AR13: High | AS13: Full case bundle present.
A14: BOM_NAS_1865_010 | B14: Bombay | C14: Nasik | D14: District Court, Nasik | E14: District Judge | F14: 1865 | G14: Debt | H14: Medium | I14: Firm | J14: Firm | K14: Landholder | L14: No | M14: No | N14: Batch filing | P14: Yes | Q14: Delayed | R14: 1-3 months | S14: No | T14: Yes | U14: No | W14: 2 | X14: Defendant absence | Y14: Ex parte | Z14: 6-18 months | AA14: Yes | AB14: 6-18 months | AC14: No | AD14: Yes | AE14: Moveables | AF14: Yes | AG14: No | AH14: No | AI14: No | AJ14: Full recovery | AK14: Yes | AL14: Withdrawal | AM14: No | AN14: Yes | AO14: No | AP14: No customary deference noted | AQ14: Delayed coercion | AR14: High | AS14: Full case bundle present.
A15: BOM_AHM_1907_011 | B15: Bombay | C15: Ahmednagar | D15: Court of the Sub. Judge, Ahmednagar | E15: Subordinate Judge | F15: 1907 | G15: Mortgage | H15: Medium | I15: Firm | J15: Firm | K15: Cultivator | L15: No | M15: No | N15: Single plaint | P15: Yes | Q15: Failed | R15: <1 month | S15: No | T15: Yes | U15: No | W15: 2 | X15: Defendant absence | Y15: Ex parte | Z15: <6 months | AA15: Yes | AB15: 6-18 months | AC15: No | AD15: No | AE15: Cash | AF15: No | AG15: No | AH15: No | AI15: No | AJ15: Partial | AK15: Yes | AL15: Withdrawal | AM15: No | AN15: No | AO15: No | AP15: No customary deference noted | AQ15: Negotiated exit | AR15: High | AS15: Full case bundle present.
A16: BOM_SAT_1895_012 | B16: Bombay | C16: Satara | D16: Munsif Court, Satara | E16: Munsif | F16: 1895 | G16: Debt | H16: Medium | I16: Merchant | J16: Individual | K16: Tenant | L16: No | M16: No | N16: Single plaint | P16: Yes | Q16: Successful | R16: 1-3 months | S16: Yes | T16: No | U16: Yes | V16: Reported absent in princely territory | W16: 0 | X16: Harvest | Y16: Contested | Z16: 6-18 months | AA16: Yes | AB16: 6-18 months | AC16: Yes | AD16: Yes | AE16: Moveables | AF16: Yes | AG16: Yes | AH16: Yes | AI16: No | AJ16: Full recovery | AK16: Yes | AL16: Abandonment | AM16: No | AN16: No | AO16: No | AP16: No customary deference noted | AQ16: Delayed coercion | AR16: Medium | AS16: Case reconstructed from decree register; plaint missing.
A17: BOM_AHM_1890_013 | B17: Bombay | C17: Ahmednagar | D17: Munsif Court, Ahmednagar | E17: Munsif | F17: 1890 | G17: Mortgage | H17: Medium | I17: Moneylender | J17: Individual | K17: Proprietor | L17: Yes | M17: No | N17: Batch filing | P17: Yes | Q17: Successful | R17: >3 months | S17: No | T17: Yes | U17: Yes | V17: Reported absent in princely territory | W17: 3 | X17: Defendant absence | Y17: Ex parte | Z17: >18 months | AA17: Yes | AB17: 6-18 months | AC17: No | AD17: No | AE17: Cash | AF17: Yes | AG17: Yes | AH17: Yes | AI17: No | AJ17: Partial | AK17: Yes | AL17: Withdrawal | AM17: No | AN17: No | AO17: No | AP17: No customary deference noted | AQ17: Delayed coercion | AR17: Low | AS17: Case reconstructed from decree register; plaint missing.
A18: BOM_NAS_1902_014 | B18: Bombay | C18: Nasik | D18: Munsif Court, Nasik | E18: Munsif | F18: 1902 | G18: Debt | H18: Medium | I18: Merchant | J18: Individual | K18: Cultivator | L18: No | M18: No | N18: Single plaint | P18: Yes | Q18: Successful | R18: 1-3 months | S18: Yes | T18: No | U18: No | W18: 3 | X18: Court congestion | Y18: Contested | Z18: 6-18 months | AA18: Yes | AB18: 6-18 months | AC18: No | AD18: Yes | AE18: Land | AF18: Yes | AG18: Yes | AH18: Yes | AI18: Yes | AJ18: Partial | AK18: Yes | AL18: Withdrawal | AM18: No | AN18: No | AO18: No | AP18: No customary deference noted | AQ18: Jurisdictional evasion | AR18: Low | AS18: Case reconstructed from decree register; plaint missing.
A19: BOM_NAS_1900_015 | B19: Bombay | C19: Nasik | D19: District Court, Nasik | E19: District Judge | F19: 1900 | G19: Debt | H19: High | I19: Trader | J19: Individual | K19: Proprietor | L19: No | M19: No | N19: Single plaint | P19: Yes | Q19: Successful | R19: 1-3 months | S19: Yes | T19: No | U19: No | W19: 3 | X19: Court congestion | Y19: Ex parte | Z19: 6-18 months | AA19: No | AB19: 6-18 months | AC19: No | AD19: No | AE19: Cash | AF19: No | AG19: No | AH19: No | AI19: No | AJ19: Full recovery | AK19: Yes | AL19: Abandonment | AM19: No | AN19: No | AO19: No | AP19: No customary deference noted | AQ19: Delayed coercion | AR19: High | AS19: Full case bundle present.
A20: BOM_KOL_1887_016 | B20: Bombay | C20: Kolaba | D20: District Court, Kolaba | E20: District Judge | F20: 1887 | G20: Mixed | H20: High | I20: Merchant | J20: Individual | K20: Landholder | L20: No | M20: Yes | N20: Single plaint | P20: Yes | Q20: Successful | R20: <1 month | S20: Yes | T20: No | U20: No | W20: 1 | X20: Defendant absence | Y20: Contested | Z20: <6 months | AA20: Yes | AB20: >18 months | AC20: Yes | AD20: No | AE20: Land | AF20: Yes | AG20: No | AH20: No | AI20: No | AJ20: Partial | AK20: Yes | AL20: Withdrawal | AM20: No | AN20: No | AO20: No | AP20: No customary deference noted | AQ20: Rapid enforcement | AR20: Medium | AS20: Case reconstructed from decree register; plaint missing.
A21: BOM_RAT_1873_017 | B21: Bombay | C21: Ratnagiri | D21: Court of the Sub. Judge, Ratnagiri | E21: Subordinate Judge | F21: 1873 | G21: Mortgage | H21: Low | I21: Firm | J21: Firm | K21: Tenant | L21: No | M21: Yes | N21: Single plaint | P21: Yes | Q21: Successful | R21: 1-3 months | S21: Yes | T21: No | U21: No | W21: 4 | X21: Defendant absence | Y21: Ex parte | Z21: 6-18 months | AA21: Yes | AB21: 6-18 months | AC21: No | AD21: No | AE21: Land | AF21: Yes | AG21: Yes | AH21: Yes | AI21: No | AJ21: Full recovery | AK21: Yes | AL21: Abandonment | AM21: No | AN21: Yes | AO21: No | AP21: No customary deference noted | AQ21: Negotiated exit | AR21: High | AS21: Full case bundle present.
A22: BOM_AHM_1895_018 | B22: Bombay | C22: Ahmednagar | D22: Court of the Sub. Judge, Ahmednagar | E22: Subordinate Judge | F22: 1895 | G22: Debt | H22: High | I22: Trader | J22: Individual | K22: Landholder | L22: Yes | M22: No | N22: Single plaint | P22: Yes | Q22: Delayed | R22: <1 month | S22: No | T22: Yes | U22: No | W22: 1 | X22: Defendant absence | Y22: Ex parte | Z22: 6-18 months | AA22: Yes | AB22: <6 months | AC22: No | AD22: No | AE22: Moveables | AF22: Yes | AG22: Yes | AH22: Yes | AI22: Yes | AJ22: Failed | AK22: Yes | AL22: Abandonment | AM22: No | AN22: No | AO22: No | AP22: No customary deference noted | AQ22: Rapid enforcement | AR22: High | AS22: Full case bundle present.
A23: BOM_RAT_1909_019 | B23: Bombay | C23: Ratnagiri | D23: Court of the Sub. Judge, Ratnagiri | E23: Subordinate Judge | F23: 1909 | G23: Mortgage | H23: Medium | I23: Merchant | J23: Individual | K23: Proprietor | L23: No | M23: No | N23: Single plaint | P23: Yes | Q23: Successful | R23: >3 months | S23: Yes | T23: No | U23: No | W23: 5 | X23: Defendant absence | Y23: Ex parte | Z23: >18 months | AA23: No | AB23: 6-18 months | AC23: No | AD23: No | AE23: Land | AF23: Yes | AG23: No | AH23: No | AI23: No | AJ23: Full recovery | AK23: Yes | AL23: Withdrawal | AM23: No | AN23: Yes | AO23: No | AP23: No customary deference noted | AQ23: Delayed coercion | AR23: High | AS23: Full case bundle present.
A24: BOM_SAT_1901_020 | B24: Bombay | C24: Satara | D24: Court of the Sub. Judge, Satara | E24: Subordinate Judge | F24: 1901 | G24: Mixed | H24: Medium | I24: Landlord | J24: Individual | K24: Proprietor | L24: No | M24: Yes | N24: Single plaint | P24: Yes | Q24: Delayed | R24: <1 month | S24: No | T24: Yes | U24: No | W24: 1 | X24: Court congestion | Y24: Ex parte | Z24: >18 months | AA24: Yes | AB24: >18 months | AC24: No | AD24: Yes | AE24: Cash | AF24: Yes | AG24: Yes | AH24: Yes | AI24: No | AJ24: Failed | AK24: No | AM24: No | AN24: No | AO24: No | AP24: No customary deference noted | AQ24: Negotiated exit | AR24: High | AS24: Full case bundle present.
A25: BOM_NAS_1874_021 | B25: Bombay | C25: Nasik | D25: Munsif Court, Nasik | E25: Munsif | F25: 1874 | G25: Bond | H25: Low | I25: Firm | J25: Firm | K25: Proprietor | L25: Yes | M25: No | N25: Single plaint | P25: Yes | Q25: Failed | R25: <1 month | S25: No | T25: Yes | U25: Yes | V25: Reported absent in princely territory | W25: 4 | X25: Court congestion | Y25: Ex parte | Z25: 6-18 months | AA25: Yes | AB25: >18 months | AC25: No | AD25: No | AE25: Cash | AF25: Yes | AG25: Yes | AH25: Yes | AI25: No | AJ25: Partial | AK25: Yes | AL25: Withdrawal | AM25: No | AN25: Yes | AO25: No | AP25: No customary deference noted | AQ25: Delayed coercion | AR25: High | AS25: Full case bundle present.
A26: BOM_SAT_1906_022 | B26: Bombay | C26: Satara | D26: District Court, Satara | E26: District Judge | F26: 1906 | G26: Mixed | H26: High | I26: Merchant | J26: Individual | K26: Landholder | L26: No | M26: No | N26: Single plaint | P26: Yes | Q26: Successful | R26: >3 months | S26: Yes | T26: No | U26: No | W26: 1 | X26: Court congestion | Y26: Contested | Z26: <6 months | AA26: Yes | AB26: >18 months | AC26: No | AD26: No | AE26: Moveables | AF26: No | AG26: No | AH26: No | AI26: No | AJ26: Failed | AK26: Yes | AL26: Withdrawal | AM26: No | AN26: Yes | AO26: No | AP26: No customary deference noted | AQ26: Negotiated exit | AR26: High | AS26: Full case bundle present.
A27: BOM_NAS_1895_023 | B27: Bombay | C27: Nasik | D27: District Court, Nasik | E27: District Judge | F27: 1895 | G27: Debt | H27: High | I27: Merchant | J27: Individual | K27: Proprietor | L27: Yes | M27: No | N27: Single plaint | P27: Yes | Q27: Successful | R27: <1 month | S27: Yes | T27: No | U27: No | W27: 3 | X27: Court congestion | Y27: Contested | Z27: <6 months | AA27: Yes | AB27: <6 months | AC27: No | AD27: No | AE27: Land | AF27: Yes | AG27: Yes | AH27: Yes | AI27: No | AJ27: Full recovery | AK27: Yes | AL27: Withdrawal | AM27: No | AN27: Yes | AO27: No | AP27: No customary deference noted | AQ27: Delayed coercion | AR27: High | AS27: Full case bundle present.
A28: BOM_AHM_1900_024 | B28: Bombay | C28: Ahmednagar | D28: Munsif Court, Ahmednagar | E28: Munsif | F28: 1900 | G28: Mortgage | H28: Low | I28: Merchant | J28: Individual | K28: Landholder | L28: No | M28: No | N28: Single plaint | P28: Yes | Q28: Failed | R28: <1 month | S28: No | T28: Yes | U28: No | W28: 1 | X28: Defendant absence | Y28: Ex parte | Z28: 6-18 months | AA28: Yes | AB28: <6 months | AC28: Yes | AD28: Yes | AE28: Cash | AF28: Yes | AG28: Yes | AH28: Yes | AI28: No | AJ28: Full recovery | AK28: Yes | AL28: Withdrawal | AM28: No | AN28: No | AO28: No | AP28: No customary deference noted | AQ28: Delayed coercion | AR28: High | AS28: Full case bundle present.
A29: BOM_POO_1892_025 | B29: Bombay | C29: Poona | D29: Court of the Sub. Judge, Poona | E29: Subordinate Judge | F29: 1892 | G29: Debt | H29: Low | I29: Landlord | J29: Individual | K29: Cultivator | L29: No | M29: Yes | N29: Batch filing | P29: Yes | Q29: Successful | R29: >3 months | S29: Yes | T29: No | U29: Yes | V29: Reported absent in princely territory | W29: 1 | X29: Defendant absence | Y29: Ex parte | Z29: 6-18 months | AA29: Yes | AB29: <6 months | AC29: No | AD29: No | AE29: Moveables | AF29: No | AG29: No | AH29: No | AI29: No | AJ29: Full recovery | AK29: Yes | AL29: Abandonment | AM29: No | AN29: Yes | AO29: No | AP29: No customary deference noted | AQ29: Jurisdictional evasion | AR29: High | AS29: Full case bundle present.
A30: BOM_RAT_1886_026 | B30: Bombay | C30: Ratnagiri | D30: District Court, Ratnagiri | E30: District Judge | F30: 1886 | G30: Mortgage | H30: Medium | I30: Moneylender | J30: Individual | K30: Tenant | L30: Yes | M30: No | N30: Single plaint | P30: Yes | Q30: Successful | R30: 1-3 months | S30: Yes | T30: No | U30: No | W30: 3 | X30: Defendant absence | Y30: Contested | Z30: <6 months | AA30: Yes | AB30: >18 months | AC30: Yes | AD30: No | AE30: Cash | AF30: Yes | AG30: Yes | AH30: Yes | AI30: No | AJ30: Failed | AK30: Yes | AL30: Satisfaction | AM30: No | AN30: Yes | AO30: No | AP30: No customary deference noted | AQ30: Negotiated exit | AR30: Medium | AS30: Case reconstructed from decree register; plaint missing.
A31: BOM_RAT_1896_027 | B31: Bombay | C31: Ratnagiri | D31: Court of the Sub. Judge, Ratnagiri | E31: Subordinate Judge | F31: 1896 | G31: Debt | H31: Medium | I31: Trader | J31: Individual | K31: Landholder | L31: No | M31: No | N31: Single plaint | P31: Yes | Q31: Successful | R31: >3 months | S31: No | T31: Yes | U31: No | W31: 5 | X31: Defendant absence | Y31: Ex parte | Z31: <6 months | AA31: Yes | AB31: >18 months | AC31: No | AD31: No | AE31: Land | AF31: Yes | AG31: Yes | AH31: Yes | AI31: No | AJ31: Full recovery | AK31: Yes | AL31: Satisfaction | AM31: No | AN31: No | AO31: No | AP31: No customary deference noted | AQ31: Procedural attrition | AR31: Low | AS31: Case reconstructed from decree register; plaint missing.
A32: PUN_RAW_1915_028 | B32: Punjab | C32: Rawalpindi | D32: District Court, Rawalpindi | E32: District Judge | F32: 1915 | G32: Mixed | H32: Low | I32: Landlord | J32: Individual | K32: Landholder | L32: No | M32: No | N32: Single plaint | P32: Yes | Q32: Delayed | R32: <1 month | S32: No | T32: Yes | U32: No | W32: 6 | X32: Court congestion | Y32: Ex parte | Z32: 6-18 months | AA32: No | AB32: >18 months | AC32: No | AD32: No | AE32: Cash | AF32: No | AG32: No | AH32: No | AI32: No | AJ32: Full recovery | AK32: Yes | AL32: Withdrawal | AM32: Yes | AN32: No | AO32: No | AP32: No customary deference noted | AQ32: Negotiated exit | AR32: High | AS32: Full case bundle present.
A33: PUN_AMR_1884_029 | B33: Punjab | C33: Amritsar | D33: District Court, Amritsar | E33: District Judge | F33: 1884 | G33: Bond | H33: High | I33: Landlord | J33: Individual | K33: Cultivator | L33: No | M33: No | N33: Batch filing | P33: Yes | Q33: Successful | R33: <1 month | S33: Yes | T33: No | U33: No | W33: 7 | X33: Defendant absence | Y33: Contested | Z33: >18 months | AA33: Yes | AB33: <6 months | AC33: No | AD33: No | AE33: Land | AF33: Yes | AG33: No | AH33: No | AI33: No | AJ33: Failed | AK33: Yes | AL33: Withdrawal | AM33: Yes | AN33: Yes | AO33: Yes | AP33: Applied customary interest cap (damdupat) | AQ33: Delayed coercion | AR33: High | AS33: Full case bundle present.
A34: PUN_MUL_1891_030 | B34: Punjab | C34: Multan | D34: Court of the Sub. Judge, Multan | E34: Subordinate Judge | F34: 1891 | G34: Mortgage | H34: Medium | I34: Merchant | J34: Individual | K34: Cultivator | L34: No | M34: No | N34: Single plaint | P34: Yes | Q34: Delayed | R34: 1-3 months | S34: No | T34: Yes | U34: No | W34: 8 | X34: Defendant absence | Y34: Ex parte | Z34: <6 months | AA34: Yes | AB34: >18 months | AC34: No | AD34: No | AE34: Land | AF34: Yes | AG34: Yes | AH34: Yes | AI34: No | AJ34: Partial | AK34: Yes | AL34: Withdrawal | AM34: Yes | AN34: No | AO34: No | AP34: No customary deference noted | AQ34: Procedural attrition | AR34: Medium | AS34: Case reconstructed from decree register; plaint missing.
A35: PUN_RAW_1912_031 | B35: Punjab | C35: Rawalpindi | D35: Munsif Court, Rawalpindi | E35: Munsif | F35: 1912 | G35: Bond | H35: High | I35: Landlord | J35: Individual | K35: Proprietor | L35: No | M35: No | N35: Batch filing | P35: Yes | Q35: Successful | R35: <1 month | S35: No | T35: Yes | U35: No | W35: 5 | X35: Court congestion | Y35: Ex parte | Z35: >18 months | AA35: Yes | AB35: 6-18 months | AC35: No | AD35: No | AE35: Moveables | AF35: Yes | AG35: No | AH35: No | AI35: No | AJ35: Partial | AK35: Yes | AL35: Withdrawal | AM35: No | AN35: No | AO35: No | AP35: No customary deference noted | AQ35: Procedural attrition | AR35: Medium | AS35: Case reconstructed from decree register; plaint missing.
A36: PUN_HIS_1908_032 | B36: Punjab | C36: Hissar | D36: Court of the Sub. Judge, Hissar | E36: Subordinate Judge | F36: 1908 | G36: Mixed | H36: High | I36: Moneylender | J36: Individual | K36: Tenant | L36: No | M36: Yes | N36: Single plaint | P36: Yes | Q36: Failed | R36: >3 months | S36: No | T36: Yes | U36: Yes | V36: Reported absent in princely territory | W36: 6 | X36: Harvest | Y36: Ex parte | Z36: >18 months | AA36: Yes | AB36: <6 months | AC36: No | AD36: No | AE36: Cash | AF36: No | AG36: No | AH36: No | AI36: No | AJ36: Partial | AK36: Yes | AL36: Withdrawal | AM36: No | AN36: No | AO36: No | AP36: No customary deference noted | AQ36: Delayed coercion | AR36: High | AS36: Full case bundle present.
A37: PUN_LUD_1883_033 | B37: Punjab | C37: Ludhiana | D37: Munsif Court, Ludhiana | E37: Munsif | F37: 1883 | G37: Mortgage | H37: Low | I37: Firm | J37: Firm | K37: Proprietor | L37: No | M37: No | N37: Batch filing | P37: Yes | Q37: Successful | R37: >3 months | S37: Yes | T37: No | U37: No | W37: 0 | X37: Court congestion | Y37: Ex parte | Z37: >18 months | AA37: Yes | AB37: <6 months | AC37: No | AD37: No | AE37: Moveables | AF37: No | AG37: No | AH37: No | AI37: No | AJ37: Partial | AK37: Yes | AL37: Withdrawal | AM37: Yes | AN37: Yes | AO37: No | AP37: No customary deference noted | AQ37: Procedural attrition | AR37: High | AS37: Full case bundle present.
A38: PUN_GUJ_1905_034 | B38: Punjab | C38: Gujranwala | D38: District Court, Gujranwala | E38: District Judge | F38: 1905 | G38: Bond | H38: High | I38: Trader | J38: Individual | K38: Landholder | L38: Yes | M38: No | N38: Single plaint | P38: Yes | Q38: Successful | R38: >3 months | S38: Yes | T38: No | U38: Yes | V38: Reported absent in princely territory | W38: 7 | X38: Court congestion | Y38: Ex parte | Z38: >18 months | AA38: Yes | AB38: >18 months | AC38: No | AD38: Yes | AE38: Cash | AF38: Yes | AG38: Yes | AH38: Yes | AI38: No | AJ38: Full recovery | AK38: Yes | AL38: Withdrawal | AM38: No | AN38: No | AO38: No | AP38: No customary deference noted | AQ38: Rapid enforcement | AR38: Low | AS38: Case reconstructed from decree register; plaint missing.
A39: PUN_LAH_1913_035 | B39: Punjab | C39: Lahore | D39: Munsif Court, Lahore | E39: Munsif | F39: 1913 | G39: Mortgage | H39: Low | I39: Firm | J39: Firm | K39: Tenant | L39: No | M39: No | N39: Single plaint | P39: Yes | Q39: Failed | R39: 1-3 months | S39: No | T39: Yes | U39: No | W39: 5 | X39: Court congestion | Y39: Ex parte | Z39: 6-18 months | AA39: Yes | AB39: >18 months | AC39: No | AD39: No | AE39: Land | AF39: Yes | AG39: Yes | AH39: Yes | AI39: No | AJ39: Full recovery | AK39: Yes | AL39: Withdrawal | AM39: No | AN39: No | AO39: No | AP39: No customary deference noted | AQ39: Procedural attrition | AR39: Medium | AS39: Case reconstructed from decree register; plaint missing.
A40: PUN_LUD_1893_036 | B40: Punjab | C40: Ludhiana | D40: District Court, Ludhiana | E40: District Judge | F40: 1893 | G40: Mixed | H40: High | I40: Trader | J40: Individual | K40: Proprietor | L40: Yes | M40: No | N40: Single plaint | P40: Yes | Q40: Delayed | R40: >3 months | S40: No | T40: Yes | U40: No | W40: 3 | X40: Court congestion | Y40: Ex parte | Z40: >18 months | AA40: Yes | AB40: >18 months | AC40: No | AD40: Yes | AE40: Cash | AF40: Yes | AG40: Yes | AH40: Yes | AI40: No | AJ40: Failed | AK40: Yes | AL40: Withdrawal | AM40: Yes | AN40: No | AO40: Yes | AP40: Applied customary interest cap (damdupat) | AQ40: Jurisdictional evasion | AR40: High | AS40: Full case bundle present.
...

Sheet CodeBook_Systematized
A1: A. Case Identification
A2: Column | B2: Values | C2: Definition
A3: Case_ID | B3: Text (auto) | C3: Unique identifier (Presidency_District_Year_Serial)
A4: Presidency | B4: Bombay / Punjab | C4: Jurisdictional unit for comparison
A5: District | B5: Text | C5: District court location
A6: Court_Level | B6: Munsif / Sub-Judge / District Judge | C6: Trial court level
A7: Year_Filed | B7: YYYY | C7: Year of initial filing
A8: Case_Type | B8: Debt / Mortgage / Bond / Other | C8: Primary credit instrument
A10: B. Parties
A11: Column | B11: Values | C11: Definition
A12: Creditor_Type | B12: Moneylender / Bank / Trader / Landlord | C12: Social-institutional position
A13: Debtor_Status | B13: Cultivator / Tenant / Proprietor | C13: Agrarian position
A14: Joint_Debtors | B14: Y/N | C14: Whether liability was collective
A15: Gendered_Party | B15: Y/N/Unknown | C15: Any female party involved
A17: C. Filing & Service (start of Procedure)
A18: Column | B18: Values | C18: Definition
A19: Service_Mode | B19: Personal / Substituted / Unserved | C19: How summons was effected
A20: Service_Delay | B20: 0–30 / 31–90 / 90+ days | C20: Time from filing to service
A21: Appearance | B21: Appeared / Defaulted | C21: Defendant response
A23: D. Hearing & Decree Formation
A24: Column | B24: Values | C24: Definition
A25: Ex_Parte | B25: Y/N | C25: Decree without defendant
A26: Adjournments_Count | B26: Integer | C26: Total adjournments
A27: Evidence_Type | B27: Oral / Documentary / Mixed | C27: Nature of proof
A28: Decree_Type | B28: Money / Mortgage / Conditional | C28: Nature of decree
A29: Decree_Amount | B29: Numeric | C29: Amount decreed (Rs.)
A31: E. Execution Initiation & Timing
A32: Column | B32: Values | C32: Definition
A33: Execution_Application | B33: Y/N | C33: Whether execution sought
A34: Time_to_Execution | B34: <6m / 6–12m / 12m+ | C34: Delay post-decree
A35: Stay_or_Appeal | B35: Y/N | C35: Execution interrupted
A37: F. Attachment & Sale
A38: Column | B38: Values | C38: Definition
A39: Attachment_Type | B39: Land / Crops / Moveables | C39: Asset attached
A40: Valuation_Method | B40: Official / Private / Unknown | C40: How asset valued
A41: Auction_Held | B41: Y/N | C41: Sale conducted
A42: Buyer_Type | B42: Creditor / Local / Outsider | C42: Purchaser identity
A43: Sale_Confirmed | B43: Y/N | C43: Sale confirmation
A45: G. Interaction with Local Norms (Pluralism)
A46: Column | B46: Values | C46: Definition
...

Sheet CodeBook_Raw
A1: COLUMN_NAME,ALLOWED_VALUES,DEFINITION
A2: Case_ID,Text,Unique identifier (Presidency_District_Year_Serial)
A3: Presidency,Bombay|Punjab,Jurisdiction of court
A4: District,Text,District where case was filed
A5: Court_Level,Munsif|Sub-Judge|District Judge,Trial court level
A6: Year_Filed,YYYY,Year of filing
A7: Case_Type,Debt|Mortgage|Bond|Other,Primary credit instrument
A9: Creditor_Type,Moneylender|Bank|Trader|Landlord|Other,Institutional position of creditor
A10: Debtor_Status,Cultivator|Tenant|Proprietor|Other,Agrarian status of debtor
A11: Joint_Debtors,Y|N,Multiple debtors involved
A12: Gendered_Party,Y|N|Unknown,Any female litigant involved
A14: Service_Mode,Personal|Substituted|Unserved,Method of service of summons
... A36: Preemption_Claim,Y|N,Pre-emption right asserted

Sheet Creditor_Debtor_Network
A1: Edge_ID | B1: Source_Node (Creditor) | C1: Source_Type | D1: Source_Province | E1: Source_District | F1: Target_Node (Debtor) | G1: Target_Type | H1: Target_Province | I1: Target_District | J1: Year | K1: Case_Type | L1: Claim_Value_Rs | M1: Decree_Obtained | N1: Land_Transferred | O1: Execution_Mode | P1: Network_Weight | Q1: Relationship_Type | R1: Notes
A2: EDGE_001 | B2: Abdul Karim & Co. | C2: Firm | D2: Punjab | E2: Gujranwala | F2: Dharm Das Kahar | G2: Cultivator | H2: Punjab | I2: Gujranwala | J2: 1891 | K2: Mortgage | L2: 100 | M2: Y | N2: N | O2: Moveables | P2: 1 | Q2: Recurring | R2: Imaginary data – for network visualisation (Gephi/Python)
A3: EDGE_002 | B3: Tulsi Das Seth | C3: Merchant | D3: Bombay | E3: Sholapur | F3: Shiv Dayal Jat | G3: Landholder | H3: Bombay | I3: Sholapur | J3: 1880 | K3: Mortgage | L3: 500 | M3: N | N3: N | O3: Cash | P3: 5 | Q3: Single transaction | R3: Imaginary data – for network visualisation (Gephi/Python)
A4: EDGE_003 | B4: Girdhari Lal Mahajan | C4: Moneylender | D4: Punjab | E4: Lahore | F4: Ishar Singh Kamboh | G4: Landholder | H4: Punjab | I4: Lahore | J4: 1862 | K4: Mortgage | L4: 75 | M4: N | N4: N | O4: Moveables | P4: 0.8 | Q4: Single transaction | R4: Imaginary data – for network visualisation (Gephi/Python)
A5: EDGE_004 | B5: Tulsi Das Seth | C5: Merchant | D5: Bombay | E5: Sholapur | F5: Ratan Chand Kurmi | G5: Cultivator | H5: Bombay | I5: Sholapur | J5: 1905 | K5: Bond | L5: 50 | M5: Y | N5: N | O5: Moveables | P5: 0.5 | Q5: Single transaction | R5: Imaginary data – for network visualisation (Gephi/Python)
A6: EDGE_005 | B6: Khushiram Tirath Ram | C6: Merchant | D6: Punjab | E6: Rawalpindi | F6: Nand Ram Jat | G6: Landholder | H6: Punjab | I6: Rawalpindi | J6: 1861 | K6: Mortgage | L6: 75 | M6: Y | N6: N | O6: Moveables | P6: 0.8 | Q6: Single transaction | R6: Imaginary data – for network visualisation (Gephi/Python)
A7: EDGE_006 | B7: Hiramal Chandumal | C7: Moneylender | D7: Punjab | E7: Multan | F7: Hanumant Gopal Rao | G7: Tenant | H7: Punjab | I7: Multan | J7: 1865 | K7: Bond | L7: 300 | M7: Y | N7: N | O7: Cash | P7: 3 | Q7: Recurring | R7: Imaginary data – for network visualisation (Gephi/Python)
A8: EDGE_007 | B8: Girdhari Lal Mahajan | C8: Moneylender | D8: Punjab | E8: Lahore | F8: Bhiku Ramchandra Jadhav | G8: Cultivator | H8: Punjab | I8: Lahore | J8: 1909 | K8: Bond | L8: 750 | M8: Y | N8: N | O8: Moveables | P8: 7.5 | Q8: Single transaction | R8: Imaginary data – for network visualisation (Gephi/Python)
A9: EDGE_008 | B9: Abdul Karim & Co. | C9: Firm | D9: Punjab | E9: Gujranwala | F9: Bhiku Ramchandra Jadhav | G9: Cultivator | H9: Punjab | I9: Gujranwala | J9: 1876 | K9: Bond | L9: 75 | M9: Y | N9: N | O9: Cash | P9: 0.8 | Q9: Single transaction | R9: Imaginary data – for network visualisation (Gephi/Python)
A10: EDGE_009 | B10: Nathulal Moolchand | C10: Trader | D10: Bombay | E10: Satara | F10: Shiv Dayal Jat | G10: Landholder | H10: Bombay | I10: Satara | J10: 1878 | K10: Debt | L10: 150 | M10: Y | N10: Y | O10: Land | P10: 1.5 | Q10: Single transaction | R10: Imaginary data – for network visualisation (Gephi/Python)
A11: EDGE_010 | B11: Ramchand Khemchand | C11: Moneylender | D11: Bombay | E11: Poona | F11: Gulab Singh Chamar | G11: Tenant | H11: Bombay | I11: Poona | J11: 1902 | K11: Debt | L11: 500 | M11: Y | N11: Y | O11: Moveables | P11: 5 | Q11: Single transaction | R11: Imaginary data – for network visualisation (Gephi/Python)
A12: EDGE_011 | B12: Nathulal Moolchand | C12: Trader | D12: Bombay | E12: Satara | F12: Kalu Khan | G12: Tenant | H12: Bombay | I12: Satara | J12: 1900 | K12: Bond | L12: 100 | M12: Y | N12: N | O12: Cash | P12: 1 | Q12: Recurring | R12: Imaginary data – for network visualisation (Gephi/Python)
A13: EDGE_012 | B13: Nathulal Moolchand | C13: Trader | D13: Bombay | E13: Satara | F13: Teja Singh Maan | G13: Proprietor | H13: Bombay | I13: Satara | J13: 1925 | K13: Debt | L13: 750 | M13: Y | N13: N | O13: Cash | P13: 7.5 | Q13: Single transaction | R13: Imaginary data – for network visualisation (Gephi/Python)
... A81: EDGE_080 | B81: Nathulal Moolchand | C81: Trader | D81: Bombay | E81: Satara | F81: Nand Ram Jat | G81: Landholder | H81: Bombay | I81: Satara | J81: 1910 | K81: Debt | L81: 75 | M81: Y | N81: Y | O81: Moveables | P81: 0.8 | Q81: Single transaction | R81: Imaginary data – for network visualisation (Gephi/Python)

Sheet Execution_Clusters_GIS
A1: Cluster_ID | B1: Province | C1: District | D1: Taluka | E1: Approx_Lat | F1: Approx_Long | G1: Year_Range | H1: Auction_Count | I1: Land_Transferred_Acres | J1: Dominant_Buyer_Type | K1: Creditor_Concentration | L1: Avg_Sale_Price_Rs | M1: Execution_Density | N1: Distress_Index | O1: Notes
A2: CLUST_001 | B2: Bombay | C2: Poona | D2: Haveli | E2: 18.52 | F2: 73.86 | G2: 1875-1890 | H2: 38 | I2: 420 | J2: Creditor | K2: High | L2: 187 | M2: High | N2: High | O2: Post-Deccan Famine cluster; concentrated moneylender acquisitions
A3: CLUST_002 | B3: Bombay | C3: Poona | D3: Maval | E3: 18.69 | F3: 73.52 | G3: 1878-1895 | H3: 22 | I3: 260 | J3: Local | K3: Medium | L3: 145 | M3: Medium | N3: Medium | O3: Moderate execution; some pre-emption claims recorded
A4: CLUST_003 | B4: Bombay | C4: Ahmednagar | D4: Shrigonda | E4: 18.63 | F4: 74.7 | G4: 1880-1900 | H4: 45 | I4: 510 | J4: Creditor | K4: High | L4: 210 | M4: High | N4: High | O4: Highest auction density; linked to irrigation failure
A5: CLUST_004 | B5: Bombay | C5: Ahmednagar | D5: Karjat | E5: 18.92 | F5: 74.66 | G5: 1882-1898 | H5: 17 | I5: 180 | J5: Outsider | K5: Medium | L5: 165 | M5: Medium | N5: Medium | O5: Mixed buyer profile; some village pre-emption successful
A6: CLUST_005 | B6: Bombay | C6: Sholapur | D6: Barshi | E6: 17.69 | F6: 75.69 | G6: 1885-1910 | H6: 31 | I6: 350 | J6: Creditor | K6: High | L6: 195 | M6: High | N6: High | O6: Railway corridor; commercial litigation elevated
A7: CLUST_006 | B7: Bombay | C7: Sholapur | D7: Mangalvedha | E7: 17.52 | F7: 75.46 | G7: 1888-1905 | H7: 12 | I7: 130 | J7: Local | K7: Low | L7: 120 | M7: Low | N7: Low | O7: Low frequency; damdupat invoked in several cases
A8: CLUST_007 | B8: Bombay | C8: Satara | D8: Karad | E8: 17.29 | F8: 74.18 | G8: 1870-1895 | H8: 28 | I8: 300 | J8: Creditor | K8: Medium | L8: 175 | M8: Medium | N8: High | O8: Mortgage cluster following crop failure 1876-77
A9: CLUST_008 | B9: Bombay | C9: Nasik | D9: Niphad | E9: 20.08 | F9: 74.12 | G9: 1890-1915 | H9: 19 | I9: 215 | J9: Outsider | K9: Medium | L9: 155 | M9: Medium | N9: Medium | O9: Outsider buyers from Bombay city in sale proclamations
A10: CLUST_009 | B10: Bombay | C10: Kolaba | D10: Pen | E10: 18.73 | F10: 73.08 | G10: 1875-1900 | H10: 9 | I10: 95 | J10: Local | K10: Low | L10: 105 | M10: Low | N10: Low | O10: Lower credit intensity; some salt-land disputes
A11: CLUST_010 | B11: Bombay | C11: Ratnagiri | D11: Dapoli | E11: 17.76 | F11: 73.18 | G11: 1885-1910 | H11: 6 | I11: 60 | J11: Local | K11: Low | L11: 90 | M11: Low | N11: Low | O11: Marginal credit zone; remittance economy reduces distress
A12: CLUST_011 | B12: Punjab | C12: Amritsar | D12: Ajnala | E12: 31.84 | F12: 74.75 | G12: 1880-1910 | H12: 14 | I12: 155 | J12: Creditor | K12: Medium | L12: 140 | M12: Medium | N12: Medium | O12: Moneylender activity following 1901 Land Alienation Act
A13: CLUST_012 | B13: Punjab | C13: Amritsar | D13: Tarn Taran | E13: 31.45 | F13: 74.93 | G13: 1885-1912 | H13: 11 | I13: 120 | J13: Local | K13: Low | L13: 110 | M13: Low | N13: Low | O13: Customary law deferred to; lower execution conversion
... A27: CLUST_026 | B27: Madras | C27: Bellary | D27: Hospet | E27: 15.27 | F27: 76.39 | G27: 1875-1900 | H27: 12 | I27: 135 | J27: Local | K27: Low | L27: 125 | M27: Low | N27: Low | O27: Low density; mediation through revenue officials common

Sheet Delay_Patterns_Analysis
A1: Obs_ID | B1: Province | C1: District | D1: Year | E1: Court_Level | F1: Case_Type | G1: Service_Delay_Days | H1: Adjournments_Count | I1: Time_To_Decree_Months | J1: Time_To_Execution_Months | K1: Total_Proceeding_Months | L1: Ex_Parte | M1: Stay_Or_Appeal | N1: Decree_Type | O1: Delay_Category | P1: Delay_Driver | Q1: Enforcement_Outcome | R1: Notes
A2: OBS_001 | B2: Bombay | C2: Kolaba | D2: 1915 | E2: Munsif | F2: Debt | G2: 50 | H2: 4 | I2: 15 | J2: 14 | K2: 29 | L2: N | M2: N | N2: Contested | O2: Protracted (24-48m) | P2: Appeals chain | Q2: Partial | R2: Imaginary obs.; province=Bombay
A3: OBS_002 | B3: Punjab | C3: Lahore | D3: 1922 | E3: Munsif | F3: Bond | G3: 111 | H3: 7 | I3: 11 | J3: 22 | K3: 33 | L3: Y | M3: N | N3: Ex parte | O3: Protracted (24-48m) | P3: Illness/death | Q3: Partial | R3: Imaginary obs.; province=Punjab
A4: OBS_003 | B4: Bombay | C4: Ratnagiri | D4: 1891 | E4: District Judge | F4: Debt | G4: 17 | H4: 2 | I4: 7 | J4: 8 | K4: 15 | L4: Y | M4: N | N4: Ex parte | O4: Moderate (12-24m) | P4: Creditor delay | Q4: Partial | R4: Imaginary obs.; province=Bombay
A5: OBS_004 | B5: Bombay | C5: Ahmednagar | D5: 1906 | E5: Munsif | F5: Debt | G5: 7 | H5: 2 | I5: 17 | J5: 7 | K5: 24 | L5: Y | M5: N | N5: Ex parte | O5: Protracted (24-48m) | P5: Appeals chain | Q5: Full recovery | R5: Imaginary obs.; province=Bombay
A6: OBS_005 | B6: Bombay | C6: Sholapur | D6: 1917 | E6: District Judge | F6: Mixed | G6: 20 | H6: 0 | I6: 5 | J6: 7 | K6: 12 | L6: N | M6: N | N6: Contested | O6: Moderate (12-24m) | P6: Illness/death | Q6: Partial | R6: Imaginary obs.; province=Bombay
A7: OBS_006 | B7: Punjab | C7: Lahore | D7: 1909 | E7: Munsif | F7: Bond | G7: 120 | H7: 7 | I7: 30 | J7: 6 | K7: 36 | L7: Y | M7: N | N7: Ex parte | O7: Protracted (24-48m) | P7: Court congestion | Q7: Failed | R7: Imaginary obs.; province=Punjab
A8: OBS_007 | B8: Bombay | C8: Nasik | D8: 1881 | E8: District Judge | F8: Mixed | G8: 28 | H8: 1 | I8: 11 | J8: 6 | K8: 17 | L8: N | M8: N | N8: Contested | O8: Moderate (12-24m) | P8: Creditor delay | Q8: Full recovery | R8: Imaginary obs.; province=Bombay
A9: OBS_008 | B9: Bengal | C9: Jessore | D9: 1913 | E9: Subordinate Judge | F9: Mixed | G9: 110 | H9: 0 | I9: 15 | J9: 11 | K9: 26 | L9: Y | M9: N | N9: Ex parte | O9: Protracted (24-48m) | P9: Revenue official delay | Q9: Full recovery | R9: Imaginary obs.; province=Bengal
A10: OBS_009 | B10: Bombay | C10: Kolaba | D10: 1885 | E10: Subordinate Judge | F10: Debt | G10: 24 | H10: 2 | I10: 3 | J10: 8 | K10: 11 | L10: N | M10: N | N10: Contested | O10: Rapid (<12m) | P10: Creditor delay | Q10: Partial | R10: Imaginary obs.; province=Bombay
A11: OBS_010 | B11: Bombay | C11: Sholapur | D11: 1916 | E11: Subordinate Judge | F11: Mixed | G11: 90 | H11: 4 | I11: 7 | J11: 6 | K11: 13 | L11: N | M11: Y | N11: Contested | O11: Moderate (12-24m) | P11: Creditor delay | Q11: Full recovery | R11: Imaginary obs.; province=Bombay
A12: OBS_011 | B12: Bombay | C12: Ahmednagar | D12: 1882 | E12: Subordinate Judge | F12: Bond | G12: 44 | H12: 3 | I12: 10 | J12: 7 | K12: 17 | L12: N | M12: Y | N12: Contested | O12: Moderate (12-24m) | P12: Defendant absence | Q12: Full recovery | R12: Imaginary obs.; province=Bombay
A13: OBS_012 | B13: Madras | C13: Kurnool | D13: 1885 | E13: District Judge | F13: Mortgage | G13: 97 | H13: 6 | I13: 21 | J13: 3 | K13: 24 | L13: Y | M13: N | N13: Ex parte | O13: Protracted (24-48m) | P13: Appeals chain | Q13: Partial | R13: Imaginary obs.; province=Madras
... A91: OBS_090 | B91: Punjab | C91: Amritsar | D91: 1903 | E91: Munsif | F91: Mixed | G91: 56 | H91: 2 | I91: 23 | J91: 6 | K91: 29 | L91: N | M91: Y | N91: Contested | O91: Protracted (24-48m) | P91: Harvest adjournment | Q91: Failed | R91: Imaginary obs.; province=Punjab

Sheet Summary_Dashboard
A1: MPI RESEARCH – PROCEDURAL DATASET: SUMMARY DASHBOARD
A2: NOTE: All data is imaginary / illustrative – populated for schema testing and visualisation purposes only
A4: A. CASE SAMPLE
A5: Total cases coded | B5: =COUNTA(Civil_Debt_Cases!A5:A200) -> 60
A6: Bombay Presidency | B6: =COUNTIF(Civil_Debt_Cases!B5:B200,"Bombay") -> 27
A7: Punjab Presidency | B7: =COUNTIF(Civil_Debt_Cases!B5:B200,"Punjab") -> 27
A8: Bengal (triangulation) | B8: =COUNTIF(Civil_Debt_Cases!B5:B200,"Bengal") -> 4
A9: Madras (triangulation) | B9: =COUNTIF(Civil_Debt_Cases!B5:B200,"Madras") -> 2
A10: Ex parte decrees | B10: =COUNTIF(Civil_Debt_Cases!Y5:Y200,"Ex parte") -> 47
A11: Cases with land attached | B11: =COUNTIF(Civil_Debt_Cases!AB5:AB200,"Yes") -> 0
A12: Auctions conducted | B12: =COUNTIF(Civil_Debt_Cases!AD5:AD200,"Yes") -> 11
A13: Customary law invoked (Punjab cases) | B13: =COUNTIFS(Civil_Debt_Cases!B5:B200,"Punjab",Civil_Debt_Cases!AI5:AI200,"Yes") -> 1
A16: B. CREDITOR-DEBTOR NETWORK
A17: Total edges (transactions) | B17: =COUNTA(Creditor_Debtor_Network!A2:A500) -> 80
A18: Edges with land transferred | B18: =COUNTIF(Creditor_Debtor_Network!N2:N500,"Y") -> 27
A19: Land execution mode | B19: =COUNTIF(Creditor_Debtor_Network!O2:O500,"Land") -> 24
A20: Recurring relationships | B20: =COUNTIF(Creditor_Debtor_Network!Q2:Q500,"Recurring") -> 16
A23: C. EXECUTION CLUSTERS / GIS
A24: Total clusters identified | B24: =COUNTA(Execution_Clusters_GIS!A2:A200) -> 26
A25: High-distress clusters | B25: =COUNTIF(Execution_Clusters_GIS!N2:N200,"High") -> 12
A26: Creditor-dominant buyer clusters | B26: =COUNTIF(Execution_Clusters_GIS!J2:J200,"Creditor") -> 12
A27: Total auctions (all clusters) | B27: =SUM(Execution_Clusters_GIS!H2:H200) -> 503
A28: Total land transferred – acres | B28: =SUM(Execution_Clusters_GIS!I2:I200) -> 5625
A31: D. DELAY PATTERNS
A32: Total delay observations | B32: =COUNTA(Delay_Patterns_Analysis!A2:A500) -> 90
A33: Avg proceedings – Bombay (months) | B33: =ROUND(AVERAGEIF(Delay_Patterns_Analysis!B2:B500,"Bombay",Delay_Patterns_Analysis!K2:K500),1) -> 18.8
A34: Avg proceedings – Punjab (months) | B34: =ROUND(AVERAGEIF(Delay_Patterns_Analysis!B2:B500,"Punjab",Delay_Patterns_Analysis!K2:K500),1) -> 34.4
A35: Rapid cases (<12m) | B35: =COUNTIF(Delay_Patterns_Analysis!O2:O500,"Rapid (<12m)") -> 3
A36: Extended cases (>48m) | B36: =COUNTIF(Delay_Patterns_Analysis!O2:O500,"Extended (>48m)") -> 5
A37: Ex parte share of observations | B37: =IFERROR(COUNTIF(Delay_Patterns_Analysis!L2:L500,"Y")/COUNTA(Delay_Patterns_Analysis!A2:A500),0) -> 0.42222222
